<?xml version="1.0"?>
<robot  xmlns:sensor="http://playerstage.sourceforge.net/gazebo/xmlschema/#sensor"
	xmlns:controller="http://playerstage.sourceforge.net/gazebo/xmlschema/#controller"
	xmlns:interface="http://playerstage.sourceforge.net/gazebo/xmlschema/#interface"
        xmlns:xacro="http://www.ros.org/wiki/xacro"
	name="wsg_50">

<xacro:macro name="wsg_50_xacro" params="name parent *origin tool_point">

  
  <joint name="${name}_connector_gripper_joint" type="fixed">
    <xacro:insert_block name="origin"/>
    <parent link="${parent}"/>
    <child link="${name}_connector_link"/>
  </joint>
  
  <link name="${name}_connector_link">
    <inertial>
      <mass value="0.01"/>
      <origin xyz="0 0 0"/>
      <inertia ixx="0.001" ixy="0.0" ixz="0.0" iyy="0.001" iyz="0.0" izz="0.001"/>
    </inertial>
    <visual>
      <origin rpy="0 0 0" xyz="0 0 0.007"/>
      <geometry>
        <cylinder length="0.014" radius="0.030"/>
      </geometry>
      <material name="Schunk/DarkGrey"/>
    </visual>
    <collision>
      <origin rpy="0 0 0" xyz="0 0 0.007"/>
      <geometry>
        <cylinder length="0.014" radius="0.030"/>
      </geometry>
    </collision>
  </link>
  
  <gazebo reference="${name}_connector_link">
    <material>Gazebo/Grey</material>
    <turnGravityOff>false</turnGravityOff>
  </gazebo>

  
 <joint name="${name}_anterior_gripper_joint" type="fixed">
    <origin xyz="0 0 0.014" rpy="0 0 0"/>
    <parent link="${name}_connector_link"/>
    <child link="${name}_base_link"/>
 </joint>

<!-- BASE LINK -->
 <link name="${name}_base_link">
      <inertial>
          <mass value="0.25" />
          <origin xyz="0 0 0" />
     	  <!--inertia ixx="1.0" ixy="0.0" ixz="0.0"
               iyy="100.0" iyz="0.0" 
               izz="1.0" /-->
      	  <inertia  ixx="1.0" ixy="0.0"  ixz="0.0"  iyy="1.0"  iyz="0.0"  izz="1.0" />
      </inertial>

      <visual>
          <origin xyz="0.0 0 0" rpy="0 0 0" />
          <geometry>
             <mesh filename="package://description_tools/meshes/wsg_50/WSG50_BASE_110.stl" scale="1 1 1"/>
	     <!--box size="0.146 0.05 0.0735"/-->
          </geometry>
          <material name="Schunk/DarkGrey"/>
      </visual>

      <collision>
          <origin xyz="0.0 0 0" rpy="0 0 0" />
          <geometry>
	     <!--box size="0.146 0.05 0.0735"/-->
             <mesh filename="package://description_tools/meshes/wsg_50/WSG50_BASE_110_collision.stl" scale="1.05 1.05 1.05"/>
         </geometry>
     </collision>
  </link>

  <gazebo reference="${name}_base_link">
    <material>Gazebo/Grey</material>
    <turnGravityOff>false</turnGravityOff>
  </gazebo>

  <!-- GRIPPER LEFT -->
  
  <joint name="${name}_clamping_width" type="prismatic">
     <limit lower="5.8" upper="110" effort="1.0" velocity="1.0"/>
     <origin xyz="-0.055 0 0" rpy="0 0 0" />      <!--origin xyz="-0.0067 0 0.049" rpy="0 0 0" /-->
     <parent link="${name}_base_link"/>
     <child link="${name}_mimic_link" />
     <dynamics friction="100" damping="100" />
     <axis xyz="1 0 0"/>
     <limit effort="100" velocity="100"/>
  </joint> 

  <link name="${name}_mimic_link">
      <inertial>
          <mass value="0.25" />
          <origin xyz="0 0 0" />
     	  <!--inertia ixx="1.0" ixy="0.0" ixz="0.0"
               iyy="100.0" iyz="0.0" 
               izz="1.0" /-->
      	  <inertia  ixx="1.0" ixy="0.0"  ixz="0.0"  iyy="1.0"  iyz="0.0"  izz="1.0" />
      </inertial>
  </link>
  
  <gazebo reference="${name}_mimic_link">
    <turnGravityOff>false</turnGravityOff>
  </gazebo>

  <joint name="${name}_base_joint_gripper_left" type="prismatic">
     <limit lower="-0.055" upper="-0.004" effort="1.0" velocity="1.0"/>
     <origin xyz="0 0 0" rpy="0 0 0" />      <!--origin xyz="-0.0067 0 0.049" rpy="0 0 0" /-->
     <parent link="${name}_base_link"/>
     <child link="${name}_gripper_left" />
     <dynamics friction="100" damping="100" />
     <mimic joint= "${name}_clamping_width" multiplier="-0.0005" />
     <axis xyz="1 0 0"/>
     <limit effort="100" velocity="100"/>
  </joint>


    <transmission name="${name}_base_trans_left">
     <type>transmission_interface/SimpleTransmission</type>
     <joint name="${name}_base_joint_gripper_left">
	<hardwareInterface>EffortJointInterface</hardwareInterface>
        <mechanicalReduction>1</mechanicalReduction>
        <motorTorqueConstant>1</motorTorqueConstant>
     </joint>
     <actuator name="${name}_base_motor_left">
	<hardwareInterface>EffortJointInterface</hardwareInterface>
         <mechanicalReduction>1</mechanicalReduction>
     </actuator>   
  </transmission>
  
  <transmission name="${name}_trans_clamping_width">
     <type>transmission_interface/SimpleTransmission</type>
     <joint name="${name}_clamping_width">
	<hardwareInterface>PositionJointInterface</hardwareInterface>
        <mechanicalReduction>1</mechanicalReduction>
        <motorTorqueConstant>1</motorTorqueConstant>
     </joint>
     <actuator name="${name}_motor_clamping_width">
	<mechanicalReduction>1</mechanicalReduction>
	<hardwareInterface>PositionJointInterface</hardwareInterface>
     </actuator>   
  </transmission>

  <link name="${name}_gripper_left">
      <inertial>
          <mass value="0.1" />
          <origin xyz="0 0 0" />
      <inertia ixx="1.0" ixy="0.0" ixz="0.0"
               iyy="1.0" iyz="0.0" 
               izz="1.0" />
      </inertial>

      <visual>
          <origin xyz="0 0 0" rpy="0 0 0" />
          <geometry>
             <mesh filename="package://description_tools/meshes/wsg_50/FINGERHOLD_WSG50.stl" scale="0.001 0.001 0.001"/>
	     <!--box size="0.0175 0.03 0.024"/-->
          </geometry>
	  <material name="Schunk/Black"/>
      </visual>

      <collision>
          <origin xyz="0 0 0" rpy="0 0 0" />
          <geometry>
	     <!--box size="0.0175 0.03 0.024"/-->
             <mesh filename="package://description_tools/meshes/wsg_50/FINGERHOLD_WSG50.stl" scale="0.00105 0.00105 0.00105"/>
         </geometry>
     </collision>
     <contact_coefficients kd="1.0" kp="1000.0" mu="0"/>
  </link>


  <gazebo reference="${name}_gripper_left">
    <material value="Schunk/Black"/>
    <turnGravityOff>false</turnGravityOff>
  </gazebo>

  <!-- LEFT FINGER -->

  <joint name="${name}_guide_joint_finger_left" type="fixed">
     <origin xyz="0 0 0.023" rpy="0 0 0" />
     <parent link="${name}_gripper_left"/>
     <child link="${name}_finger_left" />
     <dynamics friction="100" damping="100" />
     <axis xyz="1 0 0"/>
     <limit effort="100" velocity="100"/>
  </joint>

  <link name="${name}_finger_left">
      <inertial>
          <mass value="0.1" />
          <origin xyz="0 0 0" />
      <inertia ixx="1.0" ixy="0.0" ixz="0.0"
               iyy="1.0" iyz="0.0" 
               izz="1.0" />
      </inertial>

      <visual>
          <origin xyz="0 0 0.001" rpy="0 0 0" />
          <geometry>
             <mesh filename="package://description_tools/meshes/wsg_50/WSG50_FINGER.stl" scale="0.001 0.001 0.001"/>
          </geometry>
          <material name="Schunk/Black"/>
      </visual>

      <collision>
          <origin xyz="-0.001 0 0.001" rpy="0 0 0" />
          <geometry>
             <mesh filename="package://description_tools/meshes/wsg_50/WSG50_FINGER.stl" scale="0.001 0.001 0.001"/>
         </geometry>
     </collision>
     <contact_coefficients kd="1.0" kp="1000.0" mu="0"/>
  </link>

  <gazebo reference="${name}_finger_left">
    <material value="Schunk/Black"/>
    <turnGravityOff>false</turnGravityOff>
  </gazebo>


  <!-- GRIPPER RIGHT -->

  <joint name="${name}_base_joint_gripper_right" type="prismatic">
     <limit lower="0.003" upper="0.055" effort="1.0" velocity="1.0"/>
     <origin xyz="0 0 0" rpy="0 0 3.14159" />
     <parent link="${name}_base_link"/>
     <child link="${name}_gripper_right" />
     <axis xyz="-1 0 0"/>
     <dynamics friction="100" damping="100" />
     <limit effort="100" velocity="100"/>
     <mimic joint= "${name}_clamping_width" multiplier="0.0005" />
  </joint>

  <transmission name="${name}_base_trans_right">
     <type>transmission_interface/SimpleTransmission</type>
     <joint name="${name}_base_joint_gripper_right">
	<hardwareInterface>EffortJointInterface</hardwareInterface>
        <mechanicalReduction>1</mechanicalReduction>
        <motorTorqueConstant>1</motorTorqueConstant>
     </joint>
     <actuator name="${name}_base_motor_right">
	<hardwareInterface>EffortJointInterface</hardwareInterface>
         <mechanicalReduction>1</mechanicalReduction>
     </actuator>   
  </transmission>
	
    <link name="${name}_gripper_right">
      <inertial>
          <mass value="0.1" />
          <origin xyz="0 0 0" />
      <inertia ixx="1.0" ixy="0.0" ixz="0.0"
               iyy="1.0" iyz="0.0" 
               izz="1.0" />
      </inertial>

      <visual>
          <origin xyz="0.0 0 0" rpy="0 0 0" />
          <geometry>
             <mesh filename="package://description_tools/meshes/wsg_50/FINGERHOLD_WSG50.stl" scale="0.001 0.001 0.001"/>
	     <!--box size="0.0175 0.03 0.024"/-->
          </geometry>
          <material name="Schunk/Black"/>
      </visual>

      <collision>
          <origin xyz="0 0 0" rpy="0 0 0" />
          <geometry>
	     <!--box size="0.0175 0.03 0.024"/-->
             <mesh filename="package://description_tools/meshes/wsg_50/FINGERHOLD_WSG50.stl" scale="0.00105 0.00105 0.00105"/>
         </geometry>
     </collision>
     <contact_coefficients kd="1.0" kp="1000.0" mu="0"/>
  </link>

  <gazebo reference="gripper_right">
     <material value="Schunk/Black" />
    <turnGravityOff>false</turnGravityOff>
  </gazebo>

  <!-- RIGHT FINGER -->

  <joint name="${name}_guide_joint_finger_right" type="fixed">
     <origin xyz="0 0 0.023" rpy="0 0 0" />
     <parent link="${name}_gripper_right"/>
     <child link="${name}_finger_right" />
     <dynamics friction="100" damping="100" />
     <axis xyz="1 0 0"/>
     <limit effort="100" velocity="100"/>
  </joint>

  <link name="${name}_finger_right">
      <inertial>
          <mass value="0.1" />
          <origin xyz="0 0 0" />
      <inertia ixx="1.0" ixy="0.0" ixz="0.0"
               iyy="1.0" iyz="0.0" 
               izz="1.0" />
      </inertial>

      <visual>
          <origin xyz="0.0 0 0.001" rpy="0 0 0" />
          <geometry>
             <mesh filename="package://description_tools/meshes/wsg_50/WSG50_FINGER.stl" scale="0.001 0.001 0.001"/>
          </geometry>
          <material name="Schunk/Black"/>
      </visual>

      <collision>
          <origin xyz="-0.001 0 0.001" rpy="0 0 0" />
          <geometry>
             <mesh filename="package://description_tools/meshes/wsg_50/WSG50_FINGER.stl" scale="0.001 0.001 0.001"/>
         </geometry>
     </collision>
     <contact_coefficients kd="1.0" kp="1000.0" mu="0"/>
  </link>

  <gazebo reference="${name}_finger_right">
    <material value="Schunk/Black" />
    <turnGravityOff>false</turnGravityOff>
  </gazebo>
  
  <joint name="${name}_tool_joint" type="fixed">
     <origin xyz="0 0 0.145" rpy="0 0 0" />
     <parent link="${name}_base_link"/>
     <child link="${tool_point}" />
  </joint>
  
  <link name = "${tool_point}">
  </link>
  


</xacro:macro>

</robot>

